Workbook

Sheet Read me first
B1: GC EA assessment tool — categories
B2: Filled in as an example. Every entry below came from a keyword pass over the question wording and is ours, not yours.
B4: What we are asking you for
B5: Every question already belongs to one domain: the tab it is on. That never changes and you never type it.
B6: Some questions are also about something else. A question about encrypting a data store is a Data question and it is also about Security. A question about lifecycle cost is a Business question and it is also about Financial. Those extra subjects are the categories, and the Categories column is where they go.
B8: How to fill it in
B9: 1. Click a cell in the Categories column. A dropdown appears with the five.
B10: 2. Tick as many as apply. Most questions need none; 130 of the 176 stay empty, which means "this one is only about its own domain".
B12: If you do type into these cells instead, the tool checks every name when it reads this file and refuses the whole import if one is not recognised, naming the question it was in. A category nobody recognises would otherwise score nothing, on every screen, and never be noticed.
B14: The five you fill in
B15: Security, Privacy, Financial, Accessibility, Official Languages. Those are the whole of the Categories column.
B16: Business, Data, Application and Technology are categories too, and you never type them: a question carries the one its own tab is named after, automatically.
... B29: Ten of the 176 questions read as yes or no rather than as a maturity, which you named yourself. The Answer type column says which we think each one is, and the Answer column beside it offers the matching picker: 0 to 10 for a scale question, Yes and No for the others, and N/A on both. Our reading is provisional; change the type and the picker follows.

Sheet Business Architecture
A1: Business Architecture · Connecting strategy to execution through structured design
A2: Overall weight in GC EA score: 25%
A3: # | B3: Q# | C3: Assessment Question | D3: Categories | E3: Answer type | F3: Answer | G3: Maturity Label | H3: Notes / Evidence
A4: Defining the Current State — Section weight: 5% | F4: =IFERROR(ROUND(AVERAGE(F5:F18),1),"") | G4: 0.05
A5: S1 | B5: Q1 | C5: How thoroughly has the current state of this solution been documented, including all processes, data flows, and system dependencies? | E5: Scale 0-10 | G5: =IF(OR(F5="",NOT(ISNUMBER(F5))),"",IFERROR(VLOOKUP(F5,'Assessment Scale'!$A$3:$C$13,3,FALSE),""))
B6: Q2 | C6: What entities (data objects, records, clients, files) are currently produced, managed, or maintained by this solution? | E6: Scale 0-10 | G6: =IF(OR(F6="",NOT(ISNUMBER(F6))),"",IFERROR(VLOOKUP(F6,'Assessment Scale'!$A$3:$C$13,3,FALSE),""))
B7: Q3 | C7: Have all roles and responsibilities across stakeholders, operators, and service consumers been identified, documented, and formally accepted? | E7: Scale 0-10 | G7: =IF(OR(F7="",NOT(ISNUMBER(F7))),"",IFERROR(VLOOKUP(F7,'Assessment Scale'!$A$3:$C$13,3,FALSE),""))
B8: Q4 | C8: How well understood is the criticality of this solution to Government of Canada program delivery and citizen outcomes? | E8: Scale 0-10 | G8: =IF(OR(F8="",NOT(ISNUMBER(F8))),"",IFERROR(VLOOKUP(F8,'Assessment Scale'!$A$3:$C$13,3,FALSE),""))
B9: Q5 | C9: Are all sub-components of the current solution assessed for their individual criticality, availability, and risk exposure? | E9: Scale 0-10 | G9: =IF(OR(F9="",NOT(ISNUMBER(F9))),"",IFERROR(VLOOKUP(F9,'Assessment Scale'!$A$3:$C$13,3,FALSE),""))
B10: Q6 | C10: What is the current level of utilization and demand for the solution (transaction volumes, active users, peak load)? | E10: Scale 0-10 | G10: =IF(OR(F10="",NOT(ISNUMBER(F10))),"",IFERROR(VLOOKUP(F10,'Assessment Scale'!$A$3:$C$13,3,FALSE),""))
B11: Q7 | C11: What is the known availability, uptime, and service continuity record of the current solution? | E11: Scale 0-10 | G11: =IF(OR(F11="",NOT(ISNUMBER(F11))),"",IFERROR(VLOOKUP(F11,'Assessment Scale'!$A$3:$C$13,3,FALSE),""))
B12: Q8 | C12: How well understood are the total lifecycle costs — including build, operate, maintain, and decommission — of the current solution? | D12: Financial | E12: Scale 0-10 | G12: =IF(OR(F12="",NOT(ISNUMBER(F12))),"",IFERROR(VLOOKUP(F12,'Assessment Scale'!$A$3:$C$13,3,FALSE),""))
B13: Q9 | C13: What are the current unit economics (cost per transaction, cost per entity managed) and how are they tracked? | D13: Financial | E13: Scale 0-10 | G13: =IF(OR(F13="",NOT(ISNUMBER(F13))),"",IFERROR(VLOOKUP(F13,'Assessment Scale'!$A$3:$C$13,3,FALSE),""))
B14: Q10 | C14: How mature and current are the performance indicators for this solution, and what trends do they reflect? | E14: Scale 0-10 | G14: =IF(OR(F14="",NOT(ISNUMBER(F14))),"",IFERROR(VLOOKUP(F14,'Assessment Scale'!$A$3:$C$13,3,FALSE),""))
B15: Q11 | C15: Is the lifespan and full lifecycle of the solution mapped out, and is the current position within that lifecycle known? | E15: Scale 0-10 | G15: =IF(OR(F15="",NOT(ISNUMBER(F15))),"",IFERROR(VLOOKUP(F15,'Assessment Scale'!$A$3:$C$13,3,FALSE),""))
B16: Q12 | C16: What major events (technology refresh, contract renewal, legislative changes) are on the horizon for this solution? | E16: Scale 0-10 | G16: =IF(OR(F16="",NOT(ISNUMBER(F16))),"",IFERROR(VLOOKUP(F16,'Assessment Scale'!$A$3:$C$13,3,FALSE),""))
B17: Q13 | C17: How well understood are the specific skills, staffing levels, and capacity requirements to operate and evolve this solution? | E17: Scale 0-10 | G17: =IF(OR(F17="",NOT(ISNUMBER(F17))),"",IFERROR(VLOOKUP(F17,'Assessment Scale'!$A$3:$C$13,3,FALSE),""))
B18: Q14 | C18: How are universal requirements — accessibility, official languages, inclusion, and privacy — currently addressed in the solution? | D18: Privacy, Accessibility, Official Languages | E18: Scale 0-10 | G18: =IF(OR(F18="",NOT(ISNUMBER(F18))),"",IFERROR(VLOOKUP(F18,'Assessment Scale'!$A$3:$C$13,3,FALSE),""))
A19: Defining the Business Solution — Section weight: 25% | F19: =IFERROR(ROUND(AVERAGE(F20:F32),1),"") | G19: 0.25
A20: S2 | B20: Q15 | C20: How clearly and completely has the core business problem been defined and agreed upon by all stakeholders? | E20: Scale 0-10 | G20: =IF(OR(F20="",NOT(ISNUMBER(F20))),"",IFERROR(VLOOKUP(F20,'Assessment Scale'!$A$3:$C$13,3,FALSE),""))
B21: Q16 | C21: Is there a documented business case that articulates the expected value, outcomes, and measurable benefits of the proposed solution? | D21: Financial | E21: Scale 0-10 | G21: =IF(OR(F21="",NOT(ISNUMBER(F21))),"",IFERROR(VLOOKUP(F21,'Assessment Scale'!$A$3:$C$13,3,FALSE),""))
B22: Q17 | C22: How well do the proposed solution capabilities map to the GC Business Capability Model and existing enterprise services? | E22: Scale 0-10 | G22: =IF(OR(F22="",NOT(ISNUMBER(F22))),"",IFERROR(VLOOKUP(F22,'Assessment Scale'!$A$3:$C$13,3,FALSE),""))
B23: Q18 | C23: Have value streams been fully mapped, showing how business capabilities deliver outcomes to clients and citizens? | E23: Scale 0-10 | G23: =IF(OR(F23="",NOT(ISNUMBER(F23))),"",IFERROR(VLOOKUP(F23,'Assessment Scale'!$A$3:$C$13,3,FALSE),""))
B24: Q19 | C24: Is the solution design driven by defined user personas, journeys, and evidence-based user research? | E24: Scale 0-10 | G24: =IF(OR(F24="",NOT(ISNUMBER(F24))),"",IFERROR(VLOOKUP(F24,'Assessment Scale'!$A$3:$C$13,3,FALSE),""))
B25: Q20 | C25: How clearly are the target service levels, response times, and quality benchmarks defined for the proposed solution? | E25: Scale 0-10 | G25: =IF(OR(F25="",NOT(ISNUMBER(F25))),"",IFERROR(VLOOKUP(F25,'Assessment Scale'!$A$3:$C$13,3,FALSE),""))
B26: Q21 | C26: Has the solution's criticality to GC program delivery been assessed, and does the architecture reflect that criticality? | E26: Scale 0-10 | G26: =IF(OR(F26="",NOT(ISNUMBER(F26))),"",IFERROR(VLOOKUP(F26,'Assessment Scale'!$A$3:$C$13,3,FALSE),""))
B27: Q22 | C27: Is there a funding model and sourcing strategy that is sustainable across the full lifecycle of the solution? | D27: Financial | E27: Scale 0-10 | G27: =IF(OR(F27="",NOT(ISNUMBER(F27))),"",IFERROR(VLOOKUP(F27,'Assessment Scale'!$A$3:$C$13,3,FALSE),""))
B28: Q23 | C28: How well is the talent strategy defined, including required skills, existing capacity, training pipeline, and long-term retention? | E28: Scale 0-10 | G28: =IF(OR(F28="",NOT(ISNUMBER(F28))),"",IFERROR(VLOOKUP(F28,'Assessment Scale'!$A$3:$C$13,3,FALSE),""))
B29: Q24 | C29: Is a demand forecast available, and does the solution design account for projected growth and usage variability? | E29: Scale 0-10 | G29: =IF(OR(F29="",NOT(ISNUMBER(F29))),"",IFERROR(VLOOKUP(F29,'Assessment Scale'!$A$3:$C$13,3,FALSE),""))
B30: Q25 | C30: How well is the solution integrated within the broader GC enterprise ecosystem and aligned with whole-of-government priorities? | E30: Scale 0-10 | G30: =IF(OR(F30="",NOT(ISNUMBER(F30))),"",IFERROR(VLOOKUP(F30,'Assessment Scale'!$A$3:$C$13,3,FALSE),""))
B31: Q26 | C31: Is the solution designed to maximize reuse of existing GC shared services and platforms before building new capabilities? | E31: Scale 0-10 | G31: =IF(OR(F31="",NOT(ISNUMBER(F31))),"",IFERROR(VLOOKUP(F31,'Assessment Scale'!$A$3:$C$13,3,FALSE),""))
B32: Q27 | C32: How transparent is the solution design — is it documented, accessible, and understandable to those who rely on it? | E32: Scale 0-10 | G32: =IF(OR(F32="",NOT(ISNUMBER(F32))),"",IFERROR(VLOOKUP(F32,'Assessment Scale'!$A$3:$C$13,3,FALSE),""))
A33: Demonstrated Engagement — Section weight: 10% | F33: =IFERROR(ROUND(AVERAGE(F34:F42),1),"") | G33: 0.1
A34: S3 | B34: Q28 | C34: Have user personas, stories, and journeys been mapped and validated through direct engagement with actual users and stakeholders? | E34: Scale 0-10 | G34: =IF(OR(F34="",NOT(ISNUMBER(F34))),"",IFERROR(VLOOKUP(F34,'Assessment Scale'!$A$3:$C$13,3,FALSE),""))
B35: Q29 | C35: Are there formal, repeatable mechanisms to capture client, user, and stakeholder needs on a continuous basis? | E35: Scale 0-10 | G35: =IF(OR(F35="",NOT(ISNUMBER(F35))),"",IFERROR(VLOOKUP(F35,'Assessment Scale'!$A$3:$C$13,3,FALSE),""))
B36: Q30 | C36: How mature are feedback loops between the delivery team and end users, including Communities of Practice and regular reviews? | E36: Scale 0-10 | G36: =IF(OR(F36="",NOT(ISNUMBER(F36))),"",IFERROR(VLOOKUP(F36,'Assessment Scale'!$A$3:$C$13,3,FALSE),""))
B37: Q31 | C37: Are all roles, accountabilities, and decision rights across the solution ecosystem clearly documented in a RACI or equivalent model? | E37: Scale 0-10 | G37: =IF(OR(F37="",NOT(ISNUMBER(F37))),"",IFERROR(VLOOKUP(F37,'Assessment Scale'!$A$3:$C$13,3,FALSE),""))
B38: Q32 | C38: Is solution documentation, interactive guidance, and self-service assistance available and actively maintained for all user types? | E38: Scale 0-10 | G38: =IF(OR(F38="",NOT(ISNUMBER(F38))),"",IFERROR(VLOOKUP(F38,'Assessment Scale'!$A$3:$C$13,3,FALSE),""))
B39: Q33 | C39: How transparent is the operational status of the solution, including an offering roadmap and historical event schedule? | E39: Scale 0-10 | G39: =IF(OR(F39="",NOT(ISNUMBER(F39))),"",IFERROR(VLOOKUP(F39,'Assessment Scale'!$A$3:$C$13,3,FALSE),""))
B40: Q34 | C40: Are performance metrics (NPS, CSAT, CES, usage rates, drop-off rates) defined, measured, and reported back to stakeholders? | E40: Scale 0-10 | G40: =IF(OR(F40="",NOT(ISNUMBER(F40))),"",IFERROR(VLOOKUP(F40,'Assessment Scale'!$A$3:$C$13,3,FALSE),""))
...

Sheet Data & Information Architecture
A1: Data & Information Architecture · Turning raw data into trusted, connected insights
A2: Overall weight in GC EA score: 25%
A3: # | B3: Q# | C3: Assessment Question | D3: Categories | E3: Answer type | F3: Answer | G3: Maturity Label | H3: Notes / Evidence
A4: Defining the Current State — Section weight: 10% | F4: =IFERROR(ROUND(AVERAGE(F5:F13),1),"") | G4: 0.1
A5: S1 | B5: Q1 | C5: How well documented are current data models, entity relationships, and data-sharing agreements? | E5: Scale 0-10 | G5: =IF(OR(F5="",NOT(ISNUMBER(F5))),"",IFERROR(VLOOKUP(F5,'Assessment Scale'!$A$3:$C$13,3,FALSE),""))
B6: Q2 | C6: What is the degree of data fragmentation, duplication, and inconsistency across the current solution and its dependencies? | E6: Scale 0-10 | G6: =IF(OR(F6="",NOT(ISNUMBER(F6))),"",IFERROR(VLOOKUP(F6,'Assessment Scale'!$A$3:$C$13,3,FALSE),""))
B7: Q3 | C7: How well understood are data volumes, growth rates, residency requirements, and encryption posture? | D7: Security | E7: Scale 0-10 | G7: =IF(OR(F7="",NOT(ISNUMBER(F7))),"",IFERROR(VLOOKUP(F7,'Assessment Scale'!$A$3:$C$13,3,FALSE),""))
B8: Q4 | C8: Is the lifespan and full data lifecycle — from creation to disposition — mapped and governed? | E8: Scale 0-10 | G8: =IF(OR(F8="",NOT(ISNUMBER(F8))),"",IFERROR(VLOOKUP(F8,'Assessment Scale'!$A$3:$C$13,3,FALSE),""))
B9: Q5 | C9: Are data formats proprietary or based on open, interoperable standards? | E9: Scale 0-10 | G9: =IF(OR(F9="",NOT(ISNUMBER(F9))),"",IFERROR(VLOOKUP(F9,'Assessment Scale'!$A$3:$C$13,3,FALSE),""))
B10: Q6 | C10: How open and transparent is data publication, and is a default-open approach applied where appropriate? | E10: Scale 0-10 | G10: =IF(OR(F10="",NOT(ISNUMBER(F10))),"",IFERROR(VLOOKUP(F10,'Assessment Scale'!$A$3:$C$13,3,FALSE),""))
B11: Q7 | C11: Are analytics and trend analysis capabilities available to support decision-making from current data assets? | E11: Scale 0-10 | G11: =IF(OR(F11="",NOT(ISNUMBER(F11))),"",IFERROR(VLOOKUP(F11,'Assessment Scale'!$A$3:$C$13,3,FALSE),""))
B12: Q8 | C12: How mature are data access controls, auditing mechanisms, and the ability to trace who accessed what and when? | D12: Security | E12: Scale 0-10 | G12: =IF(OR(F12="",NOT(ISNUMBER(F12))),"",IFERROR(VLOOKUP(F12,'Assessment Scale'!$A$3:$C$13,3,FALSE),""))
B13: Q9 | C13: How interoperable is the current data environment with other GC systems, programs, and platforms? | E13: Scale 0-10 | G13: =IF(OR(F13="",NOT(ISNUMBER(F13))),"",IFERROR(VLOOKUP(F13,'Assessment Scale'!$A$3:$C$13,3,FALSE),""))
A14: Data Architecture & Standards — Section weight: 40% | F14: =IFERROR(ROUND(AVERAGE(F15:F26),1),"") | G14: 0.4
A15: S2 | B15: Q10 | C15: Is there a formal, documented data model that reflects all key entities, relationships, attributes, and business rules? | E15: Scale 0-10 | G15: =IF(OR(F15="",NOT(ISNUMBER(F15))),"",IFERROR(VLOOKUP(F15,'Assessment Scale'!$A$3:$C$13,3,FALSE),""))
B16: Q11 | C16: How mature is master data management — are authoritative data sources identified, maintained, and trusted? | E16: Scale 0-10 | G16: =IF(OR(F16="",NOT(ISNUMBER(F16))),"",IFERROR(VLOOKUP(F16,'Assessment Scale'!$A$3:$C$13,3,FALSE),""))
B17: Q12 | C17: Is data lifecycle governance established, covering creation, versioning, archiving, and secure disposition? | D17: Security | E17: Scale 0-10 | G17: =IF(OR(F17="",NOT(ISNUMBER(F17))),"",IFERROR(VLOOKUP(F17,'Assessment Scale'!$A$3:$C$13,3,FALSE),""))
B18: Q13 | C18: Are international and GC data standards applied (e.g., ISO, DCAT, NIEM, GC Open Data Directive)? | E18: Scale 0-10 | G18: =IF(OR(F18="",NOT(ISNUMBER(F18))),"",IFERROR(VLOOKUP(F18,'Assessment Scale'!$A$3:$C$13,3,FALSE),""))
B19: Q14 | C19: How well defined is data lineage — can the origin, transformation, and movement of data be traced end-to-end? | E19: Scale 0-10 | G19: =IF(OR(F19="",NOT(ISNUMBER(F19))),"",IFERROR(VLOOKUP(F19,'Assessment Scale'!$A$3:$C$13,3,FALSE),""))
B20: Q15 | C20: Is comprehensive metadata management in place, enabling data discovery, classification, and contextual understanding? | E20: Scale 0-10 | G20: =IF(OR(F20="",NOT(ISNUMBER(F20))),"",IFERROR(VLOOKUP(F20,'Assessment Scale'!$A$3:$C$13,3,FALSE),""))
B21: Q16 | C21: How mature is data quality management — are completeness, accuracy, consistency, and timeliness measured and enforced? | E21: Scale 0-10 | G21: =IF(OR(F21="",NOT(ISNUMBER(F21))),"",IFERROR(VLOOKUP(F21,'Assessment Scale'!$A$3:$C$13,3,FALSE),""))
B22: Q17 | C22: Is data instrumentation in place to capture operational telemetry, audit records, and system-generated metadata? | E22: Scale 0-10 | G22: =IF(OR(F22="",NOT(ISNUMBER(F22))),"",IFERROR(VLOOKUP(F22,'Assessment Scale'!$A$3:$C$13,3,FALSE),""))
B23: Q18 | C23: Are data read/write performance requirements (volumes, IOPS, movement patterns) understood and architecturally addressed? | E23: Scale 0-10 | G23: =IF(OR(F23="",NOT(ISNUMBER(F23))),"",IFERROR(VLOOKUP(F23,'Assessment Scale'!$A$3:$C$13,3,FALSE),""))
B24: Q19 | C24: Is there a strategy for structured, semi-structured, and unstructured data that applies consistent governance across all types? | E24: Scale 0-10 | G24: =IF(OR(F24="",NOT(ISNUMBER(F24))),"",IFERROR(VLOOKUP(F24,'Assessment Scale'!$A$3:$C$13,3,FALSE),""))
B25: Q20 | C25: How well is data residency managed — are intentional copies of data tracked, controlled, and compliant with policy? | E25: Scale 0-10 | G25: =IF(OR(F25="",NOT(ISNUMBER(F25))),"",IFERROR(VLOOKUP(F25,'Assessment Scale'!$A$3:$C$13,3,FALSE),""))
B26: Q21 | C26: Does the architecture support event-driven data integration patterns and real-time data processing where needed? | E26: Scale 0-10 | G26: =IF(OR(F26="",NOT(ISNUMBER(F26))),"",IFERROR(VLOOKUP(F26,'Assessment Scale'!$A$3:$C$13,3,FALSE),""))
A27: Privacy, Protection & Compliance — Section weight: 25% | F27: =IFERROR(ROUND(AVERAGE(F28:F36),1),"") | G27: 0.25
A28: S3 | B28: Q22 | C28: Has a Privacy Impact Assessment (PIA) been completed, and does the architecture reflect its recommendations? | D28: Privacy | E28: Yes / No | G28: =IF(OR(F28="",NOT(ISNUMBER(F28))),"",IFERROR(VLOOKUP(F28,'Assessment Scale'!$A$3:$C$13,3,FALSE),""))
B29: Q23 | C29: Is Privacy by Design embedded throughout the solution, from data collection through to disposition? | D29: Privacy | E29: Scale 0-10 | G29: =IF(OR(F29="",NOT(ISNUMBER(F29))),"",IFERROR(VLOOKUP(F29,'Assessment Scale'!$A$3:$C$13,3,FALSE),""))
B30: Q24 | C30: How mature is data categorization — are all data assets classified by sensitivity, and is handling appropriate to classification? | E30: Scale 0-10 | G30: =IF(OR(F30="",NOT(ISNUMBER(F30))),"",IFERROR(VLOOKUP(F30,'Assessment Scale'!$A$3:$C$13,3,FALSE),""))
B31: Q25 | C31: Is encryption applied at rest, in transit, and in processing for all data at the appropriate sensitivity level? | D31: Security | E31: Scale 0-10 | G31: =IF(OR(F31="",NOT(ISNUMBER(F31))),"",IFERROR(VLOOKUP(F31,'Assessment Scale'!$A$3:$C$13,3,FALSE),""))
B32: Q26 | C32: Are data sovereignty requirements met — is there full awareness of where data resides, crosses borders, and is subject to foreign law? | D32: Security | E32: Scale 0-10 | G32: =IF(OR(F32="",NOT(ISNUMBER(F32))),"",IFERROR(VLOOKUP(F32,'Assessment Scale'!$A$3:$C$13,3,FALSE),""))
B33: Q27 | C33: Are data retention and disposition policies enforced, including secure deletion and legal hold capabilities? | D33: Security, Privacy | E33: Scale 0-10 | G33: =IF(OR(F33="",NOT(ISNUMBER(F33))),"",IFERROR(VLOOKUP(F33,'Assessment Scale'!$A$3:$C$13,3,FALSE),""))
B34: Q28 | C34: How well are collection limitation principles applied — is only necessary data collected, with informed consent where required? | D34: Privacy | E34: Scale 0-10 | G34: =IF(OR(F34="",NOT(ISNUMBER(F34))),"",IFERROR(VLOOKUP(F34,'Assessment Scale'!$A$3:$C$13,3,FALSE),""))
B35: Q29 | C35: Is there a documented breach response plan, and has it been tested? | D35: Security | E35: Yes / No | G35: =IF(OR(F35="",NOT(ISNUMBER(F35))),"",IFERROR(VLOOKUP(F35,'Assessment Scale'!$A$3:$C$13,3,FALSE),""))
B36: Q30 | C36: Are access controls enforced at the data level, ensuring role-based and attribute-based access is actively governed? | D36: Security | E36: Scale 0-10 | G36: =IF(OR(F36="",NOT(ISNUMBER(F36))),"",IFERROR(VLOOKUP(F36,'Assessment Scale'!$A$3:$C$13,3,FALSE),""))
A37: Accessibility, Interoperability & Usability — Section weight: 5% | F37: =IFERROR(ROUND(AVERAGE(F38:F40),1),"") | G37: 0.05
A38: S4 | B38: Q31 | C38: Does the data architecture align with FAIR principles (Findable, Accessible, Interoperable, Reusable)? | E38: Scale 0-10 | G38: =IF(OR(F38="",NOT(ISNUMBER(F38))),"",IFERROR(VLOOKUP(F38,'Assessment Scale'!$A$3:$C$13,3,FALSE),""))
B39: Q32 | C39: Are APIs and data-sharing interfaces standards-based and documented, enabling downstream consumption without tight coupling? | E39: Scale 0-10 | G39: =IF(OR(F39="",NOT(ISNUMBER(F39))),"",IFERROR(VLOOKUP(F39,'Assessment Scale'!$A$3:$C$13,3,FALSE),""))
B40: Q33 | C40: How accessible is data to authorized consumers, including other departments, partners, and (where appropriate) the public? | D40: Security | E40: Scale 0-10 | G40: =IF(OR(F40="",NOT(ISNUMBER(F40))),"",IFERROR(VLOOKUP(F40,'Assessment Scale'!$A$3:$C$13,3,FALSE),""))
...

Sheet Application & Virtual Architect
A1: Application & Virtual Architecture · Designing agile, scalable application ecosystems
A2: Overall weight in GC EA score: 25%
A3: # | B3: Q# | C3: Assessment Question | D3: Categories | E3: Answer type | F3: Answer | G3: Maturity Label | H3: Notes / Evidence
A4: Defining the Current State — Section weight: 10% | F4: =IFERROR(ROUND(AVERAGE(F5:F13),1),"") | G4: 0.1
A5: S1 | B5: Q1 | C5: Is the current application solution fully documented, including architecture diagrams, data flows, and integration points? | E5: Scale 0-10 | G5: =IF(OR(F5="",NOT(ISNUMBER(F5))),"",IFERROR(VLOOKUP(F5,'Assessment Scale'!$A$3:$C$13,3,FALSE),""))
B6: Q2 | C6: How well is the current system instrumented — are resource allocation, consumption, and application health monitored? | E6: Scale 0-10 | G6: =IF(OR(F6="",NOT(ISNUMBER(F6))),"",IFERROR(VLOOKUP(F6,'Assessment Scale'!$A$3:$C$13,3,FALSE),""))
B7: Q3 | C7: What is the outstanding technical debt, and is it formally tracked in a backlog with prioritization? | E7: Scale 0-10 | G7: =IF(OR(F7="",NOT(ISNUMBER(F7))),"",IFERROR(VLOOKUP(F7,'Assessment Scale'!$A$3:$C$13,3,FALSE),""))
B8: Q4 | C8: When are major software contracts expiring, and is there a renewal or replacement strategy in place? | E8: Scale 0-10 | G8: =IF(OR(F8="",NOT(ISNUMBER(F8))),"",IFERROR(VLOOKUP(F8,'Assessment Scale'!$A$3:$C$13,3,FALSE),""))
B9: Q5 | C9: What known security vulnerabilities exist in the current solution, and what is the remediation status? | D9: Security | E9: Scale 0-10 | G9: =IF(OR(F9="",NOT(ISNUMBER(F9))),"",IFERROR(VLOOKUP(F9,'Assessment Scale'!$A$3:$C$13,3,FALSE),""))
B10: Q6 | C10: How well understood are the delivery pipeline properties — maturity, automation, deployment frequency, and failure rate? | E10: Scale 0-10 | G10: =IF(OR(F10="",NOT(ISNUMBER(F10))),"",IFERROR(VLOOKUP(F10,'Assessment Scale'!$A$3:$C$13,3,FALSE),""))
B11: Q7 | C11: What is the degree of vendor or technology lock-in, and are exit/migration pathways understood? | E11: Scale 0-10 | G11: =IF(OR(F11="",NOT(ISNUMBER(F11))),"",IFERROR(VLOOKUP(F11,'Assessment Scale'!$A$3:$C$13,3,FALSE),""))
B12: Q8 | C12: Are all upstream and downstream application dependencies mapped and current? | E12: Scale 0-10 | G12: =IF(OR(F12="",NOT(ISNUMBER(F12))),"",IFERROR(VLOOKUP(F12,'Assessment Scale'!$A$3:$C$13,3,FALSE),""))
B13: Q9 | C13: What is the known backlog of defects, flaws, and unresolved issues, and how is it managed? | E13: Scale 0-10 | G13: =IF(OR(F13="",NOT(ISNUMBER(F13))),"",IFERROR(VLOOKUP(F13,'Assessment Scale'!$A$3:$C$13,3,FALSE),""))
A14: Application Architecture & Build Approach — Section weight: 20% | F14: =IFERROR(ROUND(AVERAGE(F15:F24),1),"") | G14: 0.2
A15: S2 | B15: Q10 | C15: Is the application type (COTS, configured, custom-built, low/no-code, assembled) clearly defined and justified? | E15: Scale 0-10 | G15: =IF(OR(F15="",NOT(ISNUMBER(F15))),"",IFERROR(VLOOKUP(F15,'Assessment Scale'!$A$3:$C$13,3,FALSE),""))
B16: Q11 | C16: Is the delivery methodology (agile, waterfall, hybrid) appropriate to the solution's context and documented? | E16: Scale 0-10 | G16: =IF(OR(F16="",NOT(ISNUMBER(F16))),"",IFERROR(VLOOKUP(F16,'Assessment Scale'!$A$3:$C$13,3,FALSE),""))
B17: Q12 | C17: How software-defined is the solution — are configuration, policy, and infrastructure managed as code? | E17: Scale 0-10 | G17: =IF(OR(F17="",NOT(ISNUMBER(F17))),"",IFERROR(VLOOKUP(F17,'Assessment Scale'!$A$3:$C$13,3,FALSE),""))
B18: Q13 | C18: Is the application designed with capabilities-based modularity, enabling components to be replaced independently? | E18: Scale 0-10 | G18: =IF(OR(F18="",NOT(ISNUMBER(F18))),"",IFERROR(VLOOKUP(F18,'Assessment Scale'!$A$3:$C$13,3,FALSE),""))
B19: Q14 | C19: How are interoperability interfaces between internal components and external applications exposed and governed? | E19: Scale 0-10 | G19: =IF(OR(F19="",NOT(ISNUMBER(F19))),"",IFERROR(VLOOKUP(F19,'Assessment Scale'!$A$3:$C$13,3,FALSE),""))
B20: Q15 | C20: Is intellectual property ownership clear, and are code licensing obligations tracked and managed? | E20: Scale 0-10 | G20: =IF(OR(F20="",NOT(ISNUMBER(F20))),"",IFERROR(VLOOKUP(F20,'Assessment Scale'!$A$3:$C$13,3,FALSE),""))
B21: Q16 | C21: How mature is code reuse — is there a shared code repository, automated integration, and published component catalogue? | E21: Scale 0-10 | G21: =IF(OR(F21="",NOT(ISNUMBER(F21))),"",IFERROR(VLOOKUP(F21,'Assessment Scale'!$A$3:$C$13,3,FALSE),""))
B22: Q17 | C22: What is the lowest required integration level (container, VM/OS, physical hardware), and is it minimized where possible? | E22: Scale 0-10 | G22: =IF(OR(F22="",NOT(ISNUMBER(F22))),"",IFERROR(VLOOKUP(F22,'Assessment Scale'!$A$3:$C$13,3,FALSE),""))
B23: Q18 | C23: Are volume, redundancy, elasticity, scalability, throttling, and observability requirements defined and implemented? | E23: Scale 0-10 | G23: =IF(OR(F23="",NOT(ISNUMBER(F23))),"",IFERROR(VLOOKUP(F23,'Assessment Scale'!$A$3:$C$13,3,FALSE),""))
B24: Q19 | C24: Is the application designed as external-facing, internal enterprise, or administrative — and is the design tailored accordingly? | E24: Scale 0-10 | G24: =IF(OR(F24="",NOT(ISNUMBER(F24))),"",IFERROR(VLOOKUP(F24,'Assessment Scale'!$A$3:$C$13,3,FALSE),""))
A25: Engineering Practices & Frameworks — Section weight: 20% | F25: =IFERROR(ROUND(AVERAGE(F26:F33),1),"") | G25: 0.2
A26: S3 | B26: Q20 | C26: How mature is the DevSecOps pipeline — including continuous integration, continuous deployment, automated testing, and security gates? | D26: Security | E26: Scale 0-10 | G26: =IF(OR(F26="",NOT(ISNUMBER(F26))),"",IFERROR(VLOOKUP(F26,'Assessment Scale'!$A$3:$C$13,3,FALSE),""))
B27: Q21 | C27: Is test coverage defined, measured, and enforced — including unit, integration, regression, performance, and security testing? | D27: Security | E27: Scale 0-10 | G27: =IF(OR(F27="",NOT(ISNUMBER(F27))),"",IFERROR(VLOOKUP(F27,'Assessment Scale'!$A$3:$C$13,3,FALSE),""))
B28: Q22 | C28: How well are coding standards, frameworks, and languages documented, enforced, and aligned with GC guidance? | E28: Scale 0-10 | G28: =IF(OR(F28="",NOT(ISNUMBER(F28))),"",IFERROR(VLOOKUP(F28,'Assessment Scale'!$A$3:$C$13,3,FALSE),""))
B29: Q23 | C29: Are accessibility standards (WCAG 2.1 AA or equivalent) embedded in the development and QA process? | D29: Accessibility | E29: Yes / No | G29: =IF(OR(F29="",NOT(ISNUMBER(F29))),"",IFERROR(VLOOKUP(F29,'Assessment Scale'!$A$3:$C$13,3,FALSE),""))
B30: Q24 | C30: Is there an algorithmic impact assessment (AIA) process in place for any AI/ML components in the application? | E30: Yes / No | G30: =IF(OR(F30="",NOT(ISNUMBER(F30))),"",IFERROR(VLOOKUP(F30,'Assessment Scale'!$A$3:$C$13,3,FALSE),""))
B31: Q25 | C31: How mature is the code review and peer review process, and is it consistently applied? | E31: Scale 0-10 | G31: =IF(OR(F31="",NOT(ISNUMBER(F31))),"",IFERROR(VLOOKUP(F31,'Assessment Scale'!$A$3:$C$13,3,FALSE),""))
B32: Q26 | C32: Are application performance benchmarks established, tested against in CI/CD, and used to gate deployments? | E32: Scale 0-10 | G32: =IF(OR(F32="",NOT(ISNUMBER(F32))),"",IFERROR(VLOOKUP(F32,'Assessment Scale'!$A$3:$C$13,3,FALSE),""))
B33: Q27 | C33: Is observability (logging, tracing, metrics) built into the application architecture from the start? | E33: Scale 0-10 | G33: =IF(OR(F33="",NOT(ISNUMBER(F33))),"",IFERROR(VLOOKUP(F33,'Assessment Scale'!$A$3:$C$13,3,FALSE),""))
A34: Solution Options & Ecosystem Strategy — Section weight: 50% | F34: =IFERROR(ROUND(AVERAGE(F35:F44),1),"") | G34: 0.5
A35: S4 | B35: Q28 | C35: Has a multi-disciplinary team — including business, security, privacy, data, and technology — been engaged in solution design? | D35: Security, Privacy | E35: Scale 0-10 | G35: =IF(OR(F35="",NOT(ISNUMBER(F35))),"",IFERROR(VLOOKUP(F35,'Assessment Scale'!$A$3:$C$13,3,FALSE),""))
B36: Q29 | C36: Were enterprise contracts and procurement pathways (GC-wide standing offers, task authorizations) explored before custom sourcing? | D36: Security | E36: Scale 0-10 | G36: =IF(OR(F36="",NOT(ISNUMBER(F36))),"",IFERROR(VLOOKUP(F36,'Assessment Scale'!$A$3:$C$13,3,FALSE),""))
B37: Q30 | C37: Was optionality fully investigated — including multi-vendor, open source, and homegrown options — with a documented rationale? | E37: Scale 0-10 | G37: =IF(OR(F37="",NOT(ISNUMBER(F37))),"",IFERROR(VLOOKUP(F37,'Assessment Scale'!$A$3:$C$13,3,FALSE),""))
B38: Q31 | C38: Is a Total Cost of Ownership (TCO) model available that includes build, operate, maintain, licensing, and exit costs? | D38: Financial | E38: Scale 0-10 | G38: =IF(OR(F38="",NOT(ISNUMBER(F38))),"",IFERROR(VLOOKUP(F38,'Assessment Scale'!$A$3:$C$13,3,FALSE),""))
B39: Q32 | C39: How well are digital sovereignty considerations addressed — are GC data and systems protected from foreign jurisdiction risk? | D39: Security | E39: Scale 0-10 | G39: =IF(OR(F39="",NOT(ISNUMBER(F39))),"",IFERROR(VLOOKUP(F39,'Assessment Scale'!$A$3:$C$13,3,FALSE),""))
B40: Q33 | C40: Is the solution designed to integrate with GC-wide shared services (Sign-In Canada, GC Notify, GC Forms, etc.) where applicable? | E40: Scale 0-10 | G40: =IF(OR(F40="",NOT(ISNUMBER(F40))),"",IFERROR(VLOOKUP(F40,'Assessment Scale'!$A$3:$C$13,3,FALSE),""))
...

Sheet Technology & Physical Architect
A1: Technology & Physical Architecture · Building resilient, sovereign infrastructure foundations
A2: Overall weight in GC EA score: 25%
A3: # | B3: Q# | C3: Assessment Question | D3: Categories | E3: Answer type | F3: Answer | G3: Maturity Label | H3: Notes / Evidence
A4: Defining the Current State — Section weight: 10% | F4: =IFERROR(ROUND(AVERAGE(F5:F11),1),"") | G4: 0.1
A5: S1 | B5: Q1 | C5: Are all details of the current solution's hosting environment — hardware, software, network, and configuration — fully documented? | E5: Scale 0-10 | G5: =IF(OR(F5="",NOT(ISNUMBER(F5))),"",IFERROR(VLOOKUP(F5,'Assessment Scale'!$A$3:$C$13,3,FALSE),""))
B6: Q2 | C6: Is the current solution healthy, with no critical alerts, capacity issues, or unresolved infrastructure-level incidents? | E6: Scale 0-10 | G6: =IF(OR(F6="",NOT(ISNUMBER(F6))),"",IFERROR(VLOOKUP(F6,'Assessment Scale'!$A$3:$C$13,3,FALSE),""))
B7: Q3 | C7: Are there any imminent changes to consumed infrastructure services, and is the solution prepared for those transitions? | E7: Scale 0-10 | G7: =IF(OR(F7="",NOT(ISNUMBER(F7))),"",IFERROR(VLOOKUP(F7,'Assessment Scale'!$A$3:$C$13,3,FALSE),""))
B8: Q4 | C8: Is the lifespan of the solution shorter than that of the infrastructure — and if not, is an upgrade plan in the backlog? | E8: Scale 0-10 | G8: =IF(OR(F8="",NOT(ISNUMBER(F8))),"",IFERROR(VLOOKUP(F8,'Assessment Scale'!$A$3:$C$13,3,FALSE),""))
B9: Q5 | C9: How well-informed is the team about their infrastructure service provider's roadmap, changes, and service performance? | E9: Scale 0-10 | G9: =IF(OR(F9="",NOT(ISNUMBER(F9))),"",IFERROR(VLOOKUP(F9,'Assessment Scale'!$A$3:$C$13,3,FALSE),""))
B10: Q6 | C10: Can infrastructure be ordered and provisioned on demand, and what lead time is required? | E10: Scale 0-10 | G10: =IF(OR(F10="",NOT(ISNUMBER(F10))),"",IFERROR(VLOOKUP(F10,'Assessment Scale'!$A$3:$C$13,3,FALSE),""))
B11: Q7 | C11: Is there a clear inventory of all infrastructure components, including versions, patch levels, and support status? | E11: Scale 0-10 | G11: =IF(OR(F11="",NOT(ISNUMBER(F11))),"",IFERROR(VLOOKUP(F11,'Assessment Scale'!$A$3:$C$13,3,FALSE),""))
A12: Infrastructure Architecture & Deployment Model — Section weight: 25% | F12: =IFERROR(ROUND(AVERAGE(F13:F22),1),"") | G12: 0.25
A13: S2 | B13: Q8 | C13: Is the physical hosting model (on-premise EDC, public cloud, private cloud, hybrid) clearly justified and documented? | E13: Scale 0-10 | G13: =IF(OR(F13="",NOT(ISNUMBER(F13))),"",IFERROR(VLOOKUP(F13,'Assessment Scale'!$A$3:$C$13,3,FALSE),""))
B14: Q9 | C14: Is the decision between shared and dedicated hardware documented with supporting rationale for cost, isolation, and performance? | D14: Financial | E14: Scale 0-10 | G14: =IF(OR(F14="",NOT(ISNUMBER(F14))),"",IFERROR(VLOOKUP(F14,'Assessment Scale'!$A$3:$C$13,3,FALSE),""))
B15: Q10 | C15: Are physical kiosks, IoT devices, or specialized hardware requirements identified and architecturally accommodated? | E15: Scale 0-10 | G15: =IF(OR(F15="",NOT(ISNUMBER(F15))),"",IFERROR(VLOOKUP(F15,'Assessment Scale'!$A$3:$C$13,3,FALSE),""))
B16: Q11 | C16: How well does the design leverage GC-wide service consolidation, shared footprint, and enterprise infrastructure services? | E16: Scale 0-10 | G16: =IF(OR(F16="",NOT(ISNUMBER(F16))),"",IFERROR(VLOOKUP(F16,'Assessment Scale'!$A$3:$C$13,3,FALSE),""))
B17: Q12 | C17: Are elasticity, burst capacity, and auto-scaling requirements defined and architecturally implemented? | E17: Scale 0-10 | G17: =IF(OR(F17="",NOT(ISNUMBER(F17))),"",IFERROR(VLOOKUP(F17,'Assessment Scale'!$A$3:$C$13,3,FALSE),""))
B18: Q13 | C18: Are High-Performance Computing (HPC) and edge computing needs assessed and addressed where applicable? | E18: Scale 0-10 | G18: =IF(OR(F18="",NOT(ISNUMBER(F18))),"",IFERROR(VLOOKUP(F18,'Assessment Scale'!$A$3:$C$13,3,FALSE),""))
B19: Q14 | C19: Is GC AI Compute (dedicated GC-owned/controlled GPU infrastructure) considered and evaluated as a first option for AI workloads? | E19: Yes / No | G19: =IF(OR(F19="",NOT(ISNUMBER(F19))),"",IFERROR(VLOOKUP(F19,'Assessment Scale'!$A$3:$C$13,3,FALSE),""))
B20: Q15 | C20: Are bandwidth, latency, and network connectivity requirements defined and met by the infrastructure design? | E20: Scale 0-10 | G20: =IF(OR(F20="",NOT(ISNUMBER(F20))),"",IFERROR(VLOOKUP(F20,'Assessment Scale'!$A$3:$C$13,3,FALSE),""))
B21: Q16 | C21: Are storage volumes, IOPS, throughput, and data tiering requirements specified and provisioned appropriately? | E21: Scale 0-10 | G21: =IF(OR(F21="",NOT(ISNUMBER(F21))),"",IFERROR(VLOOKUP(F21,'Assessment Scale'!$A$3:$C$13,3,FALSE),""))
B22: Q17 | C22: Is the deployment model designed to meet availability, recovery time, and recovery point objectives? | E22: Scale 0-10 | G22: =IF(OR(F22="",NOT(ISNUMBER(F22))),"",IFERROR(VLOOKUP(F22,'Assessment Scale'!$A$3:$C$13,3,FALSE),""))
A23: Modern Engineering Patterns & Platform Design — Section weight: 20% | F23: =IFERROR(ROUND(AVERAGE(F24:F30),1),"") | G23: 0.2
A24: S3 | B24: Q18 | C24: Is configuration and infrastructure managed as code (IaC/CaC), enabling reproducible and auditable deployments? | E24: Scale 0-10 | G24: =IF(OR(F24="",NOT(ISNUMBER(F24))),"",IFERROR(VLOOKUP(F24,'Assessment Scale'!$A$3:$C$13,3,FALSE),""))
B25: Q19 | C25: How well does the team understand and apply GC-relevant infrastructure design patterns and reference architectures? | E25: Scale 0-10 | G25: =IF(OR(F25="",NOT(ISNUMBER(F25))),"",IFERROR(VLOOKUP(F25,'Assessment Scale'!$A$3:$C$13,3,FALSE),""))
B26: Q20 | C26: Does the architecture embrace composable, modular designs and event-driven models where appropriate? | E26: Scale 0-10 | G26: =IF(OR(F26="",NOT(ISNUMBER(F26))),"",IFERROR(VLOOKUP(F26,'Assessment Scale'!$A$3:$C$13,3,FALSE),""))
B27: Q21 | C27: Is interoperability and containerization baked into the infrastructure design from the beginning? | E27: Scale 0-10 | G27: =IF(OR(F27="",NOT(ISNUMBER(F27))),"",IFERROR(VLOOKUP(F27,'Assessment Scale'!$A$3:$C$13,3,FALSE),""))
B28: Q22 | C28: Is there a documented plan and roadmap for quantum and post-quantum cryptography readiness? | D28: Security | E28: Scale 0-10 | G28: =IF(OR(F28="",NOT(ISNUMBER(F28))),"",IFERROR(VLOOKUP(F28,'Assessment Scale'!$A$3:$C$13,3,FALSE),""))
B29: Q23 | C29: How mature is the use of platform engineering practices — are developer-facing platforms self-service and well-governed? | E29: Scale 0-10 | G29: =IF(OR(F29="",NOT(ISNUMBER(F29))),"",IFERROR(VLOOKUP(F29,'Assessment Scale'!$A$3:$C$13,3,FALSE),""))
B30: Q24 | C30: Are orchestration and container management (e.g., Kubernetes) used appropriately and configured to GC standards? | E30: Scale 0-10 | G30: =IF(OR(F30="",NOT(ISNUMBER(F30))),"",IFERROR(VLOOKUP(F30,'Assessment Scale'!$A$3:$C$13,3,FALSE),""))
A31: Resilience, Sovereignty & Security — Section weight: 25% | F31: =IFERROR(ROUND(AVERAGE(F32:F39),1),"") | G31: 0.25
A32: S4 | B32: Q25 | C32: Are resilience requirements (availability tiers, fault tolerance, geo-redundancy) formally defined and validated in design? | E32: Scale 0-10 | G32: =IF(OR(F32="",NOT(ISNUMBER(F32))),"",IFERROR(VLOOKUP(F32,'Assessment Scale'!$A$3:$C$13,3,FALSE),""))
B33: Q26 | C33: Is the solution's data sovereignty posture clearly documented, including data residency and foreign access risk mitigation? | D33: Security | E33: Scale 0-10 | G33: =IF(OR(F33="",NOT(ISNUMBER(F33))),"",IFERROR(VLOOKUP(F33,'Assessment Scale'!$A$3:$C$13,3,FALSE),""))
B34: Q27 | C34: How mature is the zero-trust security architecture — is authentication, authorization, and segmentation enforced throughout? | D34: Security | E34: Scale 0-10 | G34: =IF(OR(F34="",NOT(ISNUMBER(F34))),"",IFERROR(VLOOKUP(F34,'Assessment Scale'!$A$3:$C$13,3,FALSE),""))
B35: Q28 | C35: Is encryption applied appropriately at rest, in transit, and in processing, using GC-approved cryptographic standards? | D35: Security | E35: Scale 0-10 | G35: =IF(OR(F35="",NOT(ISNUMBER(F35))),"",IFERROR(VLOOKUP(F35,'Assessment Scale'!$A$3:$C$13,3,FALSE),""))
B36: Q29 | C36: Has a Threat and Risk Assessment (TRA) or Security Assessment and Authorization (SA&A) been completed and reflected in design? | D36: Security | E36: Yes / No | G36: =IF(OR(F36="",NOT(ISNUMBER(F36))),"",IFERROR(VLOOKUP(F36,'Assessment Scale'!$A$3:$C$13,3,FALSE),""))
B37: Q30 | C37: Are security controls validated through automated security testing, vulnerability scanning, and penetration testing? | D37: Security | E37: Scale 0-10 | G37: =IF(OR(F37="",NOT(ISNUMBER(F37))),"",IFERROR(VLOOKUP(F37,'Assessment Scale'!$A$3:$C$13,3,FALSE),""))
B38: Q31 | C38: Is there a documented and tested disaster recovery plan, with defined RTO and RPO that align to business requirements? | E38: Scale 0-10 | G38: =IF(OR(F38="",NOT(ISNUMBER(F38))),"",IFERROR(VLOOKUP(F38,'Assessment Scale'!$A$3:$C$13,3,FALSE),""))
B39: Q32 | C39: Are GC Cloud Guardrails and security baseline configurations implemented and continuously validated? | D39: Security | E39: Scale 0-10 | G39: =IF(OR(F39="",NOT(ISNUMBER(F39))),"",IFERROR(VLOOKUP(F39,'Assessment Scale'!$A$3:$C$13,3,FALSE),""))
A40: Operations, Governance & Continuous Management — Section weight: 20% | F40: =IFERROR(ROUND(AVERAGE(F41:F47),1),"") | G40: 0.2
...

Sheet Assessment Scale
A1: GC Enterprise Architecture · Assessment Scale
A2: Score | B2: Colour | C2: Label | D2: Description
A3: 0 | B3: Black | C3: Absent | D3: No formal architecture. Capabilities are missing, and manual workarounds are the only way to achieve business outcomes.
A4: 1 | B4: Dark Red | C4: Critical Gaps | D4: A skeleton exists, but core capabilities (like security or data integrity) are missing. High risk of systemic failure.
A5: 2 | B5: Red | C5: Fragmented | D5: Capabilities exist in "silos." They are inconsistent, undocumented, and require constant manual intervention to stay synchronized.
A6: 3 | B6: Orange | C6: Emergent | D6: Core capabilities are present but brittle. The architecture meets the "happy path" but fails under stress or edge cases.
A7: 4 | B7: Orange-Yellow | C7: Defined | D7: The architecture meets basic functional requirements. Documentation exists, but Quality Attributes (scalability, maintainability) are an afterthought.
A8: 5 | B8: Yellow | C8: Integrated | D8: This is the Baseline. All desired capabilities are present and connected. The system is stable and performs as expected under normal conditions.
A9: 6 | B9: Yellow-Green | C9: Managed | D9: Capabilities are monitored and measured. The architecture can handle predictable growth and has basic fault tolerance.
A10: 7 | B10: Green | C10: Scalable & Secure | D10: The architecture is "hardened." It handles bursts in demand effortlessly and has proactive security measures built into the design.
A11: 8 | B11: Dark Green | C11: Agile/Extensible | D11: The architecture is modular. Adding a new desired capability does not require a rewrite; the system is designed to be plugged into and extended.
A12: 9 | B12: Blue | C12: Predictive | D12: The architecture uses telemetry and AI/ML to anticipate needs (e.g., auto-scaling before a spike or self-healing before a crash).
A13: 10 | B13: Purple | C13: Symbiotic | D13: The "North Star" state. The architecture and business strategy are one. The system is so flexible it can pivot to entirely new business models with minimal architectural friction.

Sheet Summary Dashboard
A1: GC Enterprise Architecture Assessment · Summary Dashboard
A2: Scores below are automatically calculated from the four architecture worksheets. Enter scores on each tab to populate this dashboard.
A3: Architecture Domain | B3: Score (0–10) | C3: Maturity Level | D3: GC EA Weight
A4: Business Architecture | B4: =IFERROR('Business Architecture'!F72,"") | C4: =IF(B4="","Awaiting input",IFERROR(VLOOKUP(ROUND(B4,0),'Assessment Scale'!$A$3:$C$13,3,FALSE),"Awaiting input")) | D4: 25% of overall GC EA score
A5: Data & Information Architecture | B5: =IFERROR('Data & Information Architecture'!F49,"") | C5: =IF(B5="","Awaiting input",IFERROR(VLOOKUP(ROUND(B5,0),'Assessment Scale'!$A$3:$C$13,3,FALSE),"Awaiting input")) | D5: 25% of overall GC EA score
A6: Application & Virtual Architecture | B6: =IFERROR('Application & Virtual Architect'!F46,"") | C6: =IF(B6="","Awaiting input",IFERROR(VLOOKUP(ROUND(B6,0),'Assessment Scale'!$A$3:$C$13,3,FALSE),"Awaiting input")) | D6: 25% of overall GC EA score
A7: Technology & Physical Architecture | B7: =IFERROR('Technology & Physical Architect'!F49,"") | C7: =IF(B7="","Awaiting input",IFERROR(VLOOKUP(ROUND(B7,0),'Assessment Scale'!$A$3:$C$13,3,FALSE),"Awaiting input")) | D7: 25% of overall GC EA score
A10: OVERALL GC EA MATURITY SCORE | B10: =IFERROR(ROUND((N(B4)+N(B5)+N(B6)+N(B7))/((B4<>"")+(B5<>"")+(B6<>"")+(B7<>"")),1),"") | C10: =IF(B10="","Awaiting input",IFERROR(VLOOKUP(ROUND(B10,0),'Assessment Scale'!$A$3:$C$13,3,FALSE),"Awaiting input"))
A12: Score Reference Guide
A13: Score 0–2 — Critical Risk | B13: Immediate intervention required. Core capabilities absent or severely compromised.
A14: Score 3–4 — Developing | B14: Foundational elements exist but architecture is immature and at risk under stress.
A15: Score 5–6 — Baseline Ready | B15: Core capabilities present and stable. Meets minimum GC EA expectations.
A16: Score 7–8 — Advanced | B16: Hardened, scalable, and modular. Demonstrably high-quality architecture.
A17: Score 9–10 — Leading Practice | B17: Predictive, self-optimizing, fully aligned with business strategy.
A19: Every number on this tab is calculated from the four question sheets. The four domains carry 25% each, and a domain with no answers yet is left out of the overall rather than counted as zero.
